2017-06-20 11:23:51,577 [uWSGIWorker2Core0:140356686522176] [django.request:135] [exception:handle_uncaught_exception] [ERROR]- Internal Server Error: /api/sprints/
Traceback (most recent call last):
  File "/usr/local/lib/python2.7/dist-packages/django/core/handlers/exception.py", line 41, in inner
    response = get_response(request)
  File "/usr/local/lib/python2.7/dist-packages/django/core/handlers/base.py", line 217, in _get_response
    response = self.process_exception_by_middleware(e, request)
  File "/usr/local/lib/python2.7/dist-packages/django/core/handlers/base.py", line 215, in _get_response
    response = response.render()
  File "/usr/local/lib/python2.7/dist-packages/django/template/response.py", line 107, in render
    self.content = self.rendered_content
  File "/usr/local/lib/python2.7/dist-packages/rest_framework/response.py", line 72, in rendered_content
    ret = renderer.render(self.data, accepted_media_type, context)
  File "/usr/local/lib/python2.7/dist-packages/rest_framework/renderers.py", line 703, in render
    context = self.get_context(data, accepted_media_type, renderer_context)
  File "/usr/local/lib/python2.7/dist-packages/rest_framework/renderers.py", line 680, in get_context
    'filter_form': self.get_filter_form(data, view, request),
  File "/usr/local/lib/python2.7/dist-packages/rest_framework/renderers.py", line 615, in get_filter_form
    html = backend().to_html(request, queryset, view)
  File "/usr/local/lib/python2.7/dist-packages/django_filters/rest_framework/backends.py", line 63, in to_html
    template = loader.get_template(self.template)
  File "/usr/local/lib/python2.7/dist-packages/django/template/loader.py", line 25, in get_template
    raise TemplateDoesNotExist(template_name, chain=chain)
TemplateDoesNotExist: django_filters/rest_framework/form.html
2017-06-20 11:31:11,558 [uWSGIWorker1Core0:140069617813312] [django.request:135] [exception:handle_uncaught_exception] [ERROR]- Internal Server Error: /api/sprints/
Traceback (most recent call last):
  File "/usr/local/lib/python2.7/dist-packages/django/core/handlers/exception.py", line 41, in inner
    response = get_response(request)
  File "/usr/local/lib/python2.7/dist-packages/django/core/handlers/base.py", line 217, in _get_response
    response = self.process_exception_by_middleware(e, request)
  File "/usr/local/lib/python2.7/dist-packages/django/core/handlers/base.py", line 215, in _get_response
    response = response.render()
  File "/usr/local/lib/python2.7/dist-packages/django/template/response.py", line 107, in render
    self.content = self.rendered_content
  File "/usr/local/lib/python2.7/dist-packages/rest_framework/response.py", line 72, in rendered_content
    ret = renderer.render(self.data, accepted_media_type, context)
  File "/usr/local/lib/python2.7/dist-packages/rest_framework/renderers.py", line 703, in render
    context = self.get_context(data, accepted_media_type, renderer_context)
  File "/usr/local/lib/python2.7/dist-packages/rest_framework/renderers.py", line 680, in get_context
    'filter_form': self.get_filter_form(data, view, request),
  File "/usr/local/lib/python2.7/dist-packages/rest_framework/renderers.py", line 615, in get_filter_form
    html = backend().to_html(request, queryset, view)
  File "/usr/local/lib/python2.7/dist-packages/django_filters/rest_framework/backends.py", line 63, in to_html
    template = loader.get_template(self.template)
  File "/usr/local/lib/python2.7/dist-packages/django/template/loader.py", line 25, in get_template
    raise TemplateDoesNotExist(template_name, chain=chain)
TemplateDoesNotExist: django_filters/rest_framework/form.html
2017-06-20 12:12:46,405 [uWSGIWorker1Core0:139868467717952] [django.request:135] [exception:handle_uncaught_exception] [ERROR]- Internal Server Error: /silk/
Traceback (most recent call last):
  File "/usr/local/lib/python2.7/dist-packages/django/core/handlers/exception.py", line 41, in inner
    response = get_response(request)
  File "/usr/local/lib/python2.7/dist-packages/django/core/handlers/base.py", line 187, in _get_response
    response = self.process_exception_by_middleware(e, request)
  File "/usr/local/lib/python2.7/dist-packages/django/core/handlers/base.py", line 185, in _get_response
    response = wrapped_callback(request, *callback_args, **callback_kwargs)
  File "/usr/local/lib/python2.7/dist-packages/django/views/generic/base.py", line 68, in view
    return self.dispatch(request, *args, **kwargs)
  File "/usr/local/lib/python2.7/dist-packages/django/views/generic/base.py", line 88, in dispatch
    return handler(request, *args, **kwargs)
  File "/usr/local/lib/python2.7/dist-packages/django/utils/decorators.py", line 67, in _wrapper
    return bound_func(*args, **kwargs)
  File "/usr/local/lib/python2.7/dist-packages/django/utils/decorators.py", line 63, in bound_func
    return func.__get__(self, type(self))(*args2, **kwargs2)
  File "/usr/local/lib/python2.7/dist-packages/django/utils/decorators.py", line 67, in _wrapper
    return bound_func(*args, **kwargs)
  File "/usr/local/lib/python2.7/dist-packages/django/utils/decorators.py", line 63, in bound_func
    return func.__get__(self, type(self))(*args2, **kwargs2)
  File "/usr/local/lib/python2.7/dist-packages/silk/views/summary.py", line 83, in get
    c = self._create_context(request)
  File "/usr/local/lib/python2.7/dist-packages/silk/views/summary.py", line 62, in _create_context
    raw_filters = request.session.get(self.filters_key, {})
AttributeError: 'WSGIRequest' object has no attribute 'session'
2017-06-20 12:53:54,933 [uWSGIWorker1Core0:140301607511872] [django.request:135] [exception:handle_uncaught_exception] [ERROR]- Internal Server Error: /silk/requests/
Traceback (most recent call last):
  File "/usr/local/lib/python2.7/dist-packages/django/core/handlers/exception.py", line 41, in inner
    response = get_response(request)
  File "/usr/local/lib/python2.7/dist-packages/django/core/handlers/base.py", line 187, in _get_response
    response = self.process_exception_by_middleware(e, request)
  File "/usr/local/lib/python2.7/dist-packages/django/core/handlers/base.py", line 185, in _get_response
    response = wrapped_callback(request, *callback_args, **callback_kwargs)
  File "/usr/local/lib/python2.7/dist-packages/django/views/generic/base.py", line 68, in view
    return self.dispatch(request, *args, **kwargs)
  File "/usr/local/lib/python2.7/dist-packages/django/views/generic/base.py", line 88, in dispatch
    return handler(request, *args, **kwargs)
  File "/usr/local/lib/python2.7/dist-packages/django/utils/decorators.py", line 67, in _wrapper
    return bound_func(*args, **kwargs)
  File "/usr/local/lib/python2.7/dist-packages/django/contrib/auth/decorators.py", line 22, in _wrapped_view
    if test_func(request.user):
AttributeError: 'WSGIRequest' object has no attribute 'user'
2017-06-20 13:09:30,477 [uWSGIWorker2Core0:139749166323520] [django.request:135] [exception:handle_uncaught_exception] [ERROR]- Internal Server Error: /api/userdefines/
Traceback (most recent call last):
  File "/usr/local/lib/python2.7/dist-packages/django/core/handlers/exception.py", line 41, in inner
    response = get_response(request)
  File "/usr/local/lib/python2.7/dist-packages/django/core/handlers/base.py", line 187, in _get_response
    response = self.process_exception_by_middleware(e, request)
  File "/usr/local/lib/python2.7/dist-packages/django/core/handlers/base.py", line 185, in _get_response
    response = wrapped_callback(request, *callback_args, **callback_kwargs)
  File "/usr/local/lib/python2.7/dist-packages/django/views/decorators/csrf.py", line 58, in wrapped_view
    return view_func(*args, **kwargs)
  File "/usr/local/lib/python2.7/dist-packages/rest_framework/viewsets.py", line 86, in view
    return self.dispatch(request, *args, **kwargs)
  File "/usr/local/lib/python2.7/dist-packages/rest_framework/views.py", line 489, in dispatch
    response = self.handle_exception(exc)
  File "/usr/local/lib/python2.7/dist-packages/rest_framework/views.py", line 449, in handle_exception
    self.raise_uncaught_exception(exc)
  File "/usr/local/lib/python2.7/dist-packages/rest_framework/views.py", line 486, in dispatch
    response = handler(request, *args, **kwargs)
  File "./app/views.py", line 72, in list
    return Response(serializer.data)
  File "/usr/local/lib/python2.7/dist-packages/rest_framework/serializers.py", line 739, in data
    ret = super(ListSerializer, self).data
  File "/usr/local/lib/python2.7/dist-packages/rest_framework/serializers.py", line 263, in data
    self._data = self.to_representation(self.instance)
  File "/usr/local/lib/python2.7/dist-packages/rest_framework/serializers.py", line 657, in to_representation
    self.child.to_representation(item) for item in iterable
  File "/usr/local/lib/python2.7/dist-packages/rest_framework/serializers.py", line 501, in to_representation
    ret[field.field_name] = field.to_representation(attribute)
  File "/usr/local/lib/python2.7/dist-packages/rest_framework/fields.py", line 1754, in to_representation
    return method(value)
  File "./app/serializers.py", line 73, in get_links
    request = self.context['request']
KeyError: 'request'
2017-06-20 13:40:54,150 [uWSGIWorker2Core0:140139383449408] [django.request:135] [exception:handle_uncaught_exception] [ERROR]- Internal Server Error: /api/userdefines/
Traceback (most recent call last):
  File "/usr/local/lib/python2.7/dist-packages/django/core/handlers/exception.py", line 41, in inner
    response = get_response(request)
  File "/usr/local/lib/python2.7/dist-packages/django/core/handlers/base.py", line 187, in _get_response
    response = self.process_exception_by_middleware(e, request)
  File "/usr/local/lib/python2.7/dist-packages/django/core/handlers/base.py", line 185, in _get_response
    response = wrapped_callback(request, *callback_args, **callback_kwargs)
  File "/usr/local/lib/python2.7/dist-packages/django/views/decorators/csrf.py", line 58, in wrapped_view
    return view_func(*args, **kwargs)
  File "/usr/local/lib/python2.7/dist-packages/rest_framework/viewsets.py", line 86, in view
    return self.dispatch(request, *args, **kwargs)
  File "/usr/local/lib/python2.7/dist-packages/rest_framework/views.py", line 489, in dispatch
    response = self.handle_exception(exc)
  File "/usr/local/lib/python2.7/dist-packages/rest_framework/views.py", line 449, in handle_exception
    self.raise_uncaught_exception(exc)
  File "/usr/local/lib/python2.7/dist-packages/rest_framework/views.py", line 486, in dispatch
    response = handler(request, *args, **kwargs)
  File "./app/views.py", line 72, in list
    return Response(request,serializer.data)
  File "/usr/local/lib/python2.7/dist-packages/rest_framework/serializers.py", line 739, in data
    ret = super(ListSerializer, self).data
  File "/usr/local/lib/python2.7/dist-packages/rest_framework/serializers.py", line 263, in data
    self._data = self.to_representation(self.instance)
  File "/usr/local/lib/python2.7/dist-packages/rest_framework/serializers.py", line 657, in to_representation
    self.child.to_representation(item) for item in iterable
  File "/usr/local/lib/python2.7/dist-packages/rest_framework/serializers.py", line 501, in to_representation
    ret[field.field_name] = field.to_representation(attribute)
  File "/usr/local/lib/python2.7/dist-packages/rest_framework/fields.py", line 1754, in to_representation
    return method(value)
  File "./app/serializers.py", line 73, in get_links
    request = self.context['request']
KeyError: 'request'
2017-06-20 13:41:01,149 [uWSGIWorker1Core0:140139383449408] [django.request:135] [exception:handle_uncaught_exception] [ERROR]- Internal Server Error: /api/userdefines/
Traceback (most recent call last):
  File "/usr/local/lib/python2.7/dist-packages/django/core/handlers/exception.py", line 41, in inner
    response = get_response(request)
  File "/usr/local/lib/python2.7/dist-packages/django/core/handlers/base.py", line 187, in _get_response
    response = self.process_exception_by_middleware(e, request)
  File "/usr/local/lib/python2.7/dist-packages/django/core/handlers/base.py", line 185, in _get_response
    response = wrapped_callback(request, *callback_args, **callback_kwargs)
  File "/usr/local/lib/python2.7/dist-packages/django/views/decorators/csrf.py", line 58, in wrapped_view
    return view_func(*args, **kwargs)
  File "/usr/local/lib/python2.7/dist-packages/rest_framework/viewsets.py", line 86, in view
    return self.dispatch(request, *args, **kwargs)
  File "/usr/local/lib/python2.7/dist-packages/rest_framework/views.py", line 489, in dispatch
    response = self.handle_exception(exc)
  File "/usr/local/lib/python2.7/dist-packages/rest_framework/views.py", line 449, in handle_exception
    self.raise_uncaught_exception(exc)
  File "/usr/local/lib/python2.7/dist-packages/rest_framework/views.py", line 486, in dispatch
    response = handler(request, *args, **kwargs)
  File "./app/views.py", line 72, in list
    return Response(request,serializer.data)
  File "/usr/local/lib/python2.7/dist-packages/rest_framework/serializers.py", line 739, in data
    ret = super(ListSerializer, self).data
  File "/usr/local/lib/python2.7/dist-packages/rest_framework/serializers.py", line 263, in data
    self._data = self.to_representation(self.instance)
  File "/usr/local/lib/python2.7/dist-packages/rest_framework/serializers.py", line 657, in to_representation
    self.child.to_representation(item) for item in iterable
  File "/usr/local/lib/python2.7/dist-packages/rest_framework/serializers.py", line 501, in to_representation
    ret[field.field_name] = field.to_representation(attribute)
  File "/usr/local/lib/python2.7/dist-packages/rest_framework/fields.py", line 1754, in to_representation
    return method(value)
  File "./app/serializers.py", line 73, in get_links
    request = self.context['request']
KeyError: 'request'
2017-06-20 13:41:02,445 [uWSGIWorker2Core0:140139383449408] [django.request:135] [exception:handle_uncaught_exception] [ERROR]- Internal Server Error: /api/userdefines/
Traceback (most recent call last):
  File "/usr/local/lib/python2.7/dist-packages/django/core/handlers/exception.py", line 41, in inner
    response = get_response(request)
  File "/usr/local/lib/python2.7/dist-packages/django/core/handlers/base.py", line 187, in _get_response
    response = self.process_exception_by_middleware(e, request)
  File "/usr/local/lib/python2.7/dist-packages/django/core/handlers/base.py", line 185, in _get_response
    response = wrapped_callback(request, *callback_args, **callback_kwargs)
  File "/usr/local/lib/python2.7/dist-packages/django/views/decorators/csrf.py", line 58, in wrapped_view
    return view_func(*args, **kwargs)
  File "/usr/local/lib/python2.7/dist-packages/rest_framework/viewsets.py", line 86, in view
    return self.dispatch(request, *args, **kwargs)
  File "/usr/local/lib/python2.7/dist-packages/rest_framework/views.py", line 489, in dispatch
    response = self.handle_exception(exc)
  File "/usr/local/lib/python2.7/dist-packages/rest_framework/views.py", line 449, in handle_exception
    self.raise_uncaught_exception(exc)
  File "/usr/local/lib/python2.7/dist-packages/rest_framework/views.py", line 486, in dispatch
    response = handler(request, *args, **kwargs)
  File "./app/views.py", line 72, in list
    return Response(request,serializer.data)
  File "/usr/local/lib/python2.7/dist-packages/rest_framework/serializers.py", line 739, in data
    ret = super(ListSerializer, self).data
  File "/usr/local/lib/python2.7/dist-packages/rest_framework/serializers.py", line 263, in data
    self._data = self.to_representation(self.instance)
  File "/usr/local/lib/python2.7/dist-packages/rest_framework/serializers.py", line 657, in to_representation
    self.child.to_representation(item) for item in iterable
  File "/usr/local/lib/python2.7/dist-packages/rest_framework/serializers.py", line 501, in to_representation
    ret[field.field_name] = field.to_representation(attribute)
  File "/usr/local/lib/python2.7/dist-packages/rest_framework/fields.py", line 1754, in to_representation
    return method(value)
  File "./app/serializers.py", line 73, in get_links
    request = self.context['request']
KeyError: 'request'
2017-06-20 13:45:42,554 [uWSGIWorker1Core0:140532994668352] [django.request:135] [exception:handle_uncaught_exception] [ERROR]- Internal Server Error: /api/userdefines/
Traceback (most recent call last):
  File "/usr/local/lib/python2.7/dist-packages/django/core/handlers/exception.py", line 41, in inner
    response = get_response(request)
  File "/usr/local/lib/python2.7/dist-packages/django/core/handlers/base.py", line 187, in _get_response
    response = self.process_exception_by_middleware(e, request)
  File "/usr/local/lib/python2.7/dist-packages/django/core/handlers/base.py", line 185, in _get_response
    response = wrapped_callback(request, *callback_args, **callback_kwargs)
  File "/usr/local/lib/python2.7/dist-packages/django/views/decorators/csrf.py", line 58, in wrapped_view
    return view_func(*args, **kwargs)
  File "/usr/local/lib/python2.7/dist-packages/rest_framework/viewsets.py", line 86, in view
    return self.dispatch(request, *args, **kwargs)
  File "/usr/local/lib/python2.7/dist-packages/rest_framework/views.py", line 489, in dispatch
    response = self.handle_exception(exc)
  File "/usr/local/lib/python2.7/dist-packages/rest_framework/views.py", line 449, in handle_exception
    self.raise_uncaught_exception(exc)
  File "/usr/local/lib/python2.7/dist-packages/rest_framework/views.py", line 486, in dispatch
    response = handler(request, *args, **kwargs)
  File "./app/views.py", line 72, in list
    return Response(serializer.data)
  File "/usr/local/lib/python2.7/dist-packages/rest_framework/serializers.py", line 739, in data
    ret = super(ListSerializer, self).data
  File "/usr/local/lib/python2.7/dist-packages/rest_framework/serializers.py", line 263, in data
    self._data = self.to_representation(self.instance)
  File "/usr/local/lib/python2.7/dist-packages/rest_framework/serializers.py", line 657, in to_representation
    self.child.to_representation(item) for item in iterable
  File "/usr/local/lib/python2.7/dist-packages/rest_framework/serializers.py", line 501, in to_representation
    ret[field.field_name] = field.to_representation(attribute)
  File "/usr/local/lib/python2.7/dist-packages/rest_framework/fields.py", line 1754, in to_representation
    return method(value)
  File "./app/serializers.py", line 73, in get_links
    request = self.context['request']
KeyError: 'request'
2017-06-20 13:48:14,197 [uWSGIWorker1Core0:140532994668352] [django.request:135] [exception:handle_uncaught_exception] [ERROR]- Internal Server Error: /api/userdefines/
Traceback (most recent call last):
  File "/usr/local/lib/python2.7/dist-packages/django/core/handlers/exception.py", line 41, in inner
    response = get_response(request)
  File "/usr/local/lib/python2.7/dist-packages/django/core/handlers/base.py", line 187, in _get_response
    response = self.process_exception_by_middleware(e, request)
  File "/usr/local/lib/python2.7/dist-packages/django/core/handlers/base.py", line 185, in _get_response
    response = wrapped_callback(request, *callback_args, **callback_kwargs)
  File "/usr/local/lib/python2.7/dist-packages/django/views/decorators/csrf.py", line 58, in wrapped_view
    return view_func(*args, **kwargs)
  File "/usr/local/lib/python2.7/dist-packages/rest_framework/viewsets.py", line 86, in view
    return self.dispatch(request, *args, **kwargs)
  File "/usr/local/lib/python2.7/dist-packages/rest_framework/views.py", line 489, in dispatch
    response = self.handle_exception(exc)
  File "/usr/local/lib/python2.7/dist-packages/rest_framework/views.py", line 449, in handle_exception
    self.raise_uncaught_exception(exc)
  File "/usr/local/lib/python2.7/dist-packages/rest_framework/views.py", line 486, in dispatch
    response = handler(request, *args, **kwargs)
  File "./app/views.py", line 72, in list
    return Response(serializer.data)
  File "/usr/local/lib/python2.7/dist-packages/rest_framework/serializers.py", line 739, in data
    ret = super(ListSerializer, self).data
  File "/usr/local/lib/python2.7/dist-packages/rest_framework/serializers.py", line 263, in data
    self._data = self.to_representation(self.instance)
  File "/usr/local/lib/python2.7/dist-packages/rest_framework/serializers.py", line 657, in to_representation
    self.child.to_representation(item) for item in iterable
  File "/usr/local/lib/python2.7/dist-packages/rest_framework/serializers.py", line 501, in to_representation
    ret[field.field_name] = field.to_representation(attribute)
  File "/usr/local/lib/python2.7/dist-packages/rest_framework/fields.py", line 1754, in to_representation
    return method(value)
  File "./app/serializers.py", line 73, in get_links
    request = self.context['request']
KeyError: 'request'
2017-07-04 09:53:01,395 [uWSGIWorker1Core0:140579332986688] [django.request:135] [exception:handle_uncaught_exception] [ERROR]- Internal Server Error: /api/jobs/
Traceback (most recent call last):
  File "/usr/local/lib/python2.7/dist-packages/django/core/handlers/exception.py", line 41, in inner
    response = get_response(request)
  File "/usr/local/lib/python2.7/dist-packages/django/core/handlers/base.py", line 187, in _get_response
    response = self.process_exception_by_middleware(e, request)
  File "/usr/local/lib/python2.7/dist-packages/django/core/handlers/base.py", line 185, in _get_response
    response = wrapped_callback(request, *callback_args, **callback_kwargs)
  File "/usr/local/lib/python2.7/dist-packages/django/views/decorators/csrf.py", line 58, in wrapped_view
    return view_func(*args, **kwargs)
  File "/usr/local/lib/python2.7/dist-packages/rest_framework/viewsets.py", line 86, in view
    return self.dispatch(request, *args, **kwargs)
  File "/usr/local/lib/python2.7/dist-packages/rest_framework/views.py", line 489, in dispatch
    response = self.handle_exception(exc)
  File "/usr/local/lib/python2.7/dist-packages/rest_framework/views.py", line 449, in handle_exception
    self.raise_uncaught_exception(exc)
  File "/usr/local/lib/python2.7/dist-packages/rest_framework/views.py", line 486, in dispatch
    response = handler(request, *args, **kwargs)
  File "/usr/local/lib/python2.7/dist-packages/rest_framework/mixins.py", line 42, in list
    page = self.paginate_queryset(queryset)
  File "/usr/local/lib/python2.7/dist-packages/rest_framework/generics.py", line 173, in paginate_queryset
    return self.paginator.paginate_queryset(queryset, self.request, view=self)
  File "/usr/local/lib/python2.7/dist-packages/rest_framework/pagination.py", line 214, in paginate_queryset
    self.page = paginator.page(page_number)
  File "/usr/local/lib/python2.7/dist-packages/django/core/paginator.py", line 57, in page
    number = self.validate_number(number)
  File "/usr/local/lib/python2.7/dist-packages/django/core/paginator.py", line 46, in validate_number
    if number > self.num_pages:
  File "/usr/local/lib/python2.7/dist-packages/django/utils/functional.py", line 35, in __get__
    res = instance.__dict__[self.name] = self.func(instance)
  File "/usr/local/lib/python2.7/dist-packages/django/core/paginator.py", line 91, in num_pages
    if self.count == 0 and not self.allow_empty_first_page:
  File "/usr/local/lib/python2.7/dist-packages/django/utils/functional.py", line 35, in __get__
    res = instance.__dict__[self.name] = self.func(instance)
  File "/usr/local/lib/python2.7/dist-packages/django/core/paginator.py", line 79, in count
    return self.object_list.count()
  File "/usr/local/lib/python2.7/dist-packages/django/db/models/query.py", line 364, in count
    return self.query.get_count(using=self.db)
  File "/usr/local/lib/python2.7/dist-packages/django/db/models/sql/query.py", line 499, in get_count
    number = obj.get_aggregation(using, ['__count'])['__count']
  File "/usr/local/lib/python2.7/dist-packages/django/db/models/sql/query.py", line 480, in get_aggregation
    result = compiler.execute_sql(SINGLE)
  File "/usr/local/lib/python2.7/dist-packages/silk/sql.py", line 45, in execute_sql
    return self._execute_sql(*args, **kwargs)
  File "/usr/local/lib/python2.7/dist-packages/django/db/models/sql/compiler.py", line 886, in execute_sql
    raise original_exception
ProgrammingError: (1146, "Table 'lol.jobs' doesn't exist")
2017-07-04 09:54:26,446 [uWSGIWorker1Core0:140242796070720] [django.request:135] [exception:handle_uncaught_exception] [ERROR]- Internal Server Error: /api/jobs/
Traceback (most recent call last):
  File "/usr/local/lib/python2.7/dist-packages/django/core/handlers/exception.py", line 41, in inner
    response = get_response(request)
  File "/usr/local/lib/python2.7/dist-packages/django/core/handlers/base.py", line 187, in _get_response
    response = self.process_exception_by_middleware(e, request)
  File "/usr/local/lib/python2.7/dist-packages/django/core/handlers/base.py", line 185, in _get_response
    response = wrapped_callback(request, *callback_args, **callback_kwargs)
  File "/usr/local/lib/python2.7/dist-packages/django/views/decorators/csrf.py", line 58, in wrapped_view
    return view_func(*args, **kwargs)
  File "/usr/local/lib/python2.7/dist-packages/rest_framework/viewsets.py", line 86, in view
    return self.dispatch(request, *args, **kwargs)
  File "/usr/local/lib/python2.7/dist-packages/rest_framework/views.py", line 489, in dispatch
    response = self.handle_exception(exc)
  File "/usr/local/lib/python2.7/dist-packages/rest_framework/views.py", line 449, in handle_exception
    self.raise_uncaught_exception(exc)
  File "/usr/local/lib/python2.7/dist-packages/rest_framework/views.py", line 486, in dispatch
    response = handler(request, *args, **kwargs)
  File "/usr/local/lib/python2.7/dist-packages/rest_framework/mixins.py", line 42, in list
    page = self.paginate_queryset(queryset)
  File "/usr/local/lib/python2.7/dist-packages/rest_framework/generics.py", line 173, in paginate_queryset
    return self.paginator.paginate_queryset(queryset, self.request, view=self)
  File "/usr/local/lib/python2.7/dist-packages/rest_framework/pagination.py", line 226, in paginate_queryset
    return list(self.page)
  File "/usr/local/lib/python2.7/dist-packages/django/core/paginator.py", line 137, in __len__
    return len(self.object_list)
  File "/usr/local/lib/python2.7/dist-packages/django/db/models/query.py", line 232, in __len__
    self._fetch_all()
  File "/usr/local/lib/python2.7/dist-packages/django/db/models/query.py", line 1118, in _fetch_all
    self._result_cache = list(self._iterable_class(self))
  File "/usr/local/lib/python2.7/dist-packages/django/db/models/query.py", line 53, in __iter__
    results = compiler.execute_sql(chunked_fetch=self.chunked_fetch)
  File "/usr/local/lib/python2.7/dist-packages/silk/sql.py", line 24, in execute_sql
    q, params = self.as_sql()
  File "/usr/local/lib/python2.7/dist-packages/django/db/models/sql/compiler.py", line 412, in as_sql
    extra_select, order_by, group_by = self.pre_sql_setup()
  File "/usr/local/lib/python2.7/dist-packages/django/db/models/sql/compiler.py", line 47, in pre_sql_setup
    order_by = self.get_order_by()
  File "/usr/local/lib/python2.7/dist-packages/django/db/models/sql/compiler.py", line 298, in get_order_by
    field, self.query.get_meta(), default_order=asc))
  File "/usr/local/lib/python2.7/dist-packages/django/db/models/sql/compiler.py", line 593, in find_ordering_name
    field, targets, alias, joins, path, opts = self._setup_joins(pieces, opts, alias)
  File "/usr/local/lib/python2.7/dist-packages/django/db/models/sql/compiler.py", line 626, in _setup_joins
    pieces, opts, alias)
  File "/usr/local/lib/python2.7/dist-packages/django/db/models/sql/query.py", line 1417, in setup_joins
    names, opts, allow_many, fail_on_missing=True)
  File "/usr/local/lib/python2.7/dist-packages/django/db/models/sql/query.py", line 1352, in names_to_path
    "Choices are: %s" % (name, ", ".join(available)))
FieldError: Cannot resolve keyword 'end' into field. Choices are: builds, description, id, name, recipient, svn_password, svn_url, svn_username
2017-07-04 09:54:28,468 [uWSGIWorker2Core0:140242796070720] [django.request:135] [exception:handle_uncaught_exception] [ERROR]- Internal Server Error: /api/jobs/
Traceback (most recent call last):
  File "/usr/local/lib/python2.7/dist-packages/django/core/handlers/exception.py", line 41, in inner
    response = get_response(request)
  File "/usr/local/lib/python2.7/dist-packages/django/core/handlers/base.py", line 187, in _get_response
    response = self.process_exception_by_middleware(e, request)
  File "/usr/local/lib/python2.7/dist-packages/django/core/handlers/base.py", line 185, in _get_response
    response = wrapped_callback(request, *callback_args, **callback_kwargs)
  File "/usr/local/lib/python2.7/dist-packages/django/views/decorators/csrf.py", line 58, in wrapped_view
    return view_func(*args, **kwargs)
  File "/usr/local/lib/python2.7/dist-packages/rest_framework/viewsets.py", line 86, in view
    return self.dispatch(request, *args, **kwargs)
  File "/usr/local/lib/python2.7/dist-packages/rest_framework/views.py", line 489, in dispatch
    response = self.handle_exception(exc)
  File "/usr/local/lib/python2.7/dist-packages/rest_framework/views.py", line 449, in handle_exception
    self.raise_uncaught_exception(exc)
  File "/usr/local/lib/python2.7/dist-packages/rest_framework/views.py", line 486, in dispatch
    response = handler(request, *args, **kwargs)
  File "/usr/local/lib/python2.7/dist-packages/rest_framework/mixins.py", line 42, in list
    page = self.paginate_queryset(queryset)
  File "/usr/local/lib/python2.7/dist-packages/rest_framework/generics.py", line 173, in paginate_queryset
    return self.paginator.paginate_queryset(queryset, self.request, view=self)
  File "/usr/local/lib/python2.7/dist-packages/rest_framework/pagination.py", line 226, in paginate_queryset
    return list(self.page)
  File "/usr/local/lib/python2.7/dist-packages/django/core/paginator.py", line 137, in __len__
    return len(self.object_list)
  File "/usr/local/lib/python2.7/dist-packages/django/db/models/query.py", line 232, in __len__
    self._fetch_all()
  File "/usr/local/lib/python2.7/dist-packages/django/db/models/query.py", line 1118, in _fetch_all
    self._result_cache = list(self._iterable_class(self))
  File "/usr/local/lib/python2.7/dist-packages/django/db/models/query.py", line 53, in __iter__
    results = compiler.execute_sql(chunked_fetch=self.chunked_fetch)
  File "/usr/local/lib/python2.7/dist-packages/silk/sql.py", line 24, in execute_sql
    q, params = self.as_sql()
  File "/usr/local/lib/python2.7/dist-packages/django/db/models/sql/compiler.py", line 412, in as_sql
    extra_select, order_by, group_by = self.pre_sql_setup()
  File "/usr/local/lib/python2.7/dist-packages/django/db/models/sql/compiler.py", line 47, in pre_sql_setup
    order_by = self.get_order_by()
  File "/usr/local/lib/python2.7/dist-packages/django/db/models/sql/compiler.py", line 298, in get_order_by
    field, self.query.get_meta(), default_order=asc))
  File "/usr/local/lib/python2.7/dist-packages/django/db/models/sql/compiler.py", line 593, in find_ordering_name
    field, targets, alias, joins, path, opts = self._setup_joins(pieces, opts, alias)
  File "/usr/local/lib/python2.7/dist-packages/django/db/models/sql/compiler.py", line 626, in _setup_joins
    pieces, opts, alias)
  File "/usr/local/lib/python2.7/dist-packages/django/db/models/sql/query.py", line 1417, in setup_joins
    names, opts, allow_many, fail_on_missing=True)
  File "/usr/local/lib/python2.7/dist-packages/django/db/models/sql/query.py", line 1352, in names_to_path
    "Choices are: %s" % (name, ", ".join(available)))
FieldError: Cannot resolve keyword 'end' into field. Choices are: builds, description, id, name, recipient, svn_password, svn_url, svn_username
2017-07-04 09:55:25,377 [uWSGIWorker1Core0:140242796070720] [django.request:135] [exception:handle_uncaught_exception] [ERROR]- Internal Server Error: /api/jobs/
Traceback (most recent call last):
  File "/usr/local/lib/python2.7/dist-packages/django/core/handlers/exception.py", line 41, in inner
    response = get_response(request)
  File "/usr/local/lib/python2.7/dist-packages/django/core/handlers/base.py", line 187, in _get_response
    response = self.process_exception_by_middleware(e, request)
  File "/usr/local/lib/python2.7/dist-packages/django/core/handlers/base.py", line 185, in _get_response
    response = wrapped_callback(request, *callback_args, **callback_kwargs)
  File "/usr/local/lib/python2.7/dist-packages/django/views/decorators/csrf.py", line 58, in wrapped_view
    return view_func(*args, **kwargs)
  File "/usr/local/lib/python2.7/dist-packages/rest_framework/viewsets.py", line 86, in view
    return self.dispatch(request, *args, **kwargs)
  File "/usr/local/lib/python2.7/dist-packages/rest_framework/views.py", line 489, in dispatch
    response = self.handle_exception(exc)
  File "/usr/local/lib/python2.7/dist-packages/rest_framework/views.py", line 449, in handle_exception
    self.raise_uncaught_exception(exc)
  File "/usr/local/lib/python2.7/dist-packages/rest_framework/views.py", line 486, in dispatch
    response = handler(request, *args, **kwargs)
  File "/usr/local/lib/python2.7/dist-packages/rest_framework/mixins.py", line 42, in list
    page = self.paginate_queryset(queryset)
  File "/usr/local/lib/python2.7/dist-packages/rest_framework/generics.py", line 173, in paginate_queryset
    return self.paginator.paginate_queryset(queryset, self.request, view=self)
  File "/usr/local/lib/python2.7/dist-packages/rest_framework/pagination.py", line 226, in paginate_queryset
    return list(self.page)
  File "/usr/local/lib/python2.7/dist-packages/django/core/paginator.py", line 137, in __len__
    return len(self.object_list)
  File "/usr/local/lib/python2.7/dist-packages/django/db/models/query.py", line 232, in __len__
    self._fetch_all()
  File "/usr/local/lib/python2.7/dist-packages/django/db/models/query.py", line 1118, in _fetch_all
    self._result_cache = list(self._iterable_class(self))
  File "/usr/local/lib/python2.7/dist-packages/django/db/models/query.py", line 53, in __iter__
    results = compiler.execute_sql(chunked_fetch=self.chunked_fetch)
  File "/usr/local/lib/python2.7/dist-packages/silk/sql.py", line 24, in execute_sql
    q, params = self.as_sql()
  File "/usr/local/lib/python2.7/dist-packages/django/db/models/sql/compiler.py", line 412, in as_sql
    extra_select, order_by, group_by = self.pre_sql_setup()
  File "/usr/local/lib/python2.7/dist-packages/django/db/models/sql/compiler.py", line 47, in pre_sql_setup
    order_by = self.get_order_by()
  File "/usr/local/lib/python2.7/dist-packages/django/db/models/sql/compiler.py", line 298, in get_order_by
    field, self.query.get_meta(), default_order=asc))
  File "/usr/local/lib/python2.7/dist-packages/django/db/models/sql/compiler.py", line 593, in find_ordering_name
    field, targets, alias, joins, path, opts = self._setup_joins(pieces, opts, alias)
  File "/usr/local/lib/python2.7/dist-packages/django/db/models/sql/compiler.py", line 626, in _setup_joins
    pieces, opts, alias)
  File "/usr/local/lib/python2.7/dist-packages/django/db/models/sql/query.py", line 1417, in setup_joins
    names, opts, allow_many, fail_on_missing=True)
  File "/usr/local/lib/python2.7/dist-packages/django/db/models/sql/query.py", line 1352, in names_to_path
    "Choices are: %s" % (name, ", ".join(available)))
FieldError: Cannot resolve keyword 'end' into field. Choices are: builds, description, id, name, recipient, svn_password, svn_url, svn_username
2017-07-04 09:55:26,883 [uWSGIWorker2Core0:140242796070720] [django.request:135] [exception:handle_uncaught_exception] [ERROR]- Internal Server Error: /api/jobs/
Traceback (most recent call last):
  File "/usr/local/lib/python2.7/dist-packages/django/core/handlers/exception.py", line 41, in inner
    response = get_response(request)
  File "/usr/local/lib/python2.7/dist-packages/django/core/handlers/base.py", line 187, in _get_response
    response = self.process_exception_by_middleware(e, request)
  File "/usr/local/lib/python2.7/dist-packages/django/core/handlers/base.py", line 185, in _get_response
    response = wrapped_callback(request, *callback_args, **callback_kwargs)
  File "/usr/local/lib/python2.7/dist-packages/django/views/decorators/csrf.py", line 58, in wrapped_view
    return view_func(*args, **kwargs)
  File "/usr/local/lib/python2.7/dist-packages/rest_framework/viewsets.py", line 86, in view
    return self.dispatch(request, *args, **kwargs)
  File "/usr/local/lib/python2.7/dist-packages/rest_framework/views.py", line 489, in dispatch
    response = self.handle_exception(exc)
  File "/usr/local/lib/python2.7/dist-packages/rest_framework/views.py", line 449, in handle_exception
    self.raise_uncaught_exception(exc)
  File "/usr/local/lib/python2.7/dist-packages/rest_framework/views.py", line 486, in dispatch
    response = handler(request, *args, **kwargs)
  File "/usr/local/lib/python2.7/dist-packages/rest_framework/mixins.py", line 42, in list
    page = self.paginate_queryset(queryset)
  File "/usr/local/lib/python2.7/dist-packages/rest_framework/generics.py", line 173, in paginate_queryset
    return self.paginator.paginate_queryset(queryset, self.request, view=self)
  File "/usr/local/lib/python2.7/dist-packages/rest_framework/pagination.py", line 226, in paginate_queryset
    return list(self.page)
  File "/usr/local/lib/python2.7/dist-packages/django/core/paginator.py", line 137, in __len__
    return len(self.object_list)
  File "/usr/local/lib/python2.7/dist-packages/django/db/models/query.py", line 232, in __len__
    self._fetch_all()
  File "/usr/local/lib/python2.7/dist-packages/django/db/models/query.py", line 1118, in _fetch_all
    self._result_cache = list(self._iterable_class(self))
  File "/usr/local/lib/python2.7/dist-packages/django/db/models/query.py", line 53, in __iter__
    results = compiler.execute_sql(chunked_fetch=self.chunked_fetch)
  File "/usr/local/lib/python2.7/dist-packages/silk/sql.py", line 24, in execute_sql
    q, params = self.as_sql()
  File "/usr/local/lib/python2.7/dist-packages/django/db/models/sql/compiler.py", line 412, in as_sql
    extra_select, order_by, group_by = self.pre_sql_setup()
  File "/usr/local/lib/python2.7/dist-packages/django/db/models/sql/compiler.py", line 47, in pre_sql_setup
    order_by = self.get_order_by()
  File "/usr/local/lib/python2.7/dist-packages/django/db/models/sql/compiler.py", line 298, in get_order_by
    field, self.query.get_meta(), default_order=asc))
  File "/usr/local/lib/python2.7/dist-packages/django/db/models/sql/compiler.py", line 593, in find_ordering_name
    field, targets, alias, joins, path, opts = self._setup_joins(pieces, opts, alias)
  File "/usr/local/lib/python2.7/dist-packages/django/db/models/sql/compiler.py", line 626, in _setup_joins
    pieces, opts, alias)
  File "/usr/local/lib/python2.7/dist-packages/django/db/models/sql/query.py", line 1417, in setup_joins
    names, opts, allow_many, fail_on_missing=True)
  File "/usr/local/lib/python2.7/dist-packages/django/db/models/sql/query.py", line 1352, in names_to_path
    "Choices are: %s" % (name, ", ".join(available)))
FieldError: Cannot resolve keyword 'end' into field. Choices are: builds, description, id, name, recipient, svn_password, svn_url, svn_username
2017-07-04 09:55:27,601 [uWSGIWorker1Core0:140242796070720] [django.request:135] [exception:handle_uncaught_exception] [ERROR]- Internal Server Error: /api/jobs/
Traceback (most recent call last):
  File "/usr/local/lib/python2.7/dist-packages/django/core/handlers/exception.py", line 41, in inner
    response = get_response(request)
  File "/usr/local/lib/python2.7/dist-packages/django/core/handlers/base.py", line 187, in _get_response
    response = self.process_exception_by_middleware(e, request)
  File "/usr/local/lib/python2.7/dist-packages/django/core/handlers/base.py", line 185, in _get_response
    response = wrapped_callback(request, *callback_args, **callback_kwargs)
  File "/usr/local/lib/python2.7/dist-packages/django/views/decorators/csrf.py", line 58, in wrapped_view
    return view_func(*args, **kwargs)
  File "/usr/local/lib/python2.7/dist-packages/rest_framework/viewsets.py", line 86, in view
    return self.dispatch(request, *args, **kwargs)
  File "/usr/local/lib/python2.7/dist-packages/rest_framework/views.py", line 489, in dispatch
    response = self.handle_exception(exc)
  File "/usr/local/lib/python2.7/dist-packages/rest_framework/views.py", line 449, in handle_exception
    self.raise_uncaught_exception(exc)
  File "/usr/local/lib/python2.7/dist-packages/rest_framework/views.py", line 486, in dispatch
    response = handler(request, *args, **kwargs)
  File "/usr/local/lib/python2.7/dist-packages/rest_framework/mixins.py", line 42, in list
    page = self.paginate_queryset(queryset)
  File "/usr/local/lib/python2.7/dist-packages/rest_framework/generics.py", line 173, in paginate_queryset
    return self.paginator.paginate_queryset(queryset, self.request, view=self)
  File "/usr/local/lib/python2.7/dist-packages/rest_framework/pagination.py", line 226, in paginate_queryset
    return list(self.page)
  File "/usr/local/lib/python2.7/dist-packages/django/core/paginator.py", line 137, in __len__
    return len(self.object_list)
  File "/usr/local/lib/python2.7/dist-packages/django/db/models/query.py", line 232, in __len__
    self._fetch_all()
  File "/usr/local/lib/python2.7/dist-packages/django/db/models/query.py", line 1118, in _fetch_all
    self._result_cache = list(self._iterable_class(self))
  File "/usr/local/lib/python2.7/dist-packages/django/db/models/query.py", line 53, in __iter__
    results = compiler.execute_sql(chunked_fetch=self.chunked_fetch)
  File "/usr/local/lib/python2.7/dist-packages/silk/sql.py", line 24, in execute_sql
    q, params = self.as_sql()
  File "/usr/local/lib/python2.7/dist-packages/django/db/models/sql/compiler.py", line 412, in as_sql
    extra_select, order_by, group_by = self.pre_sql_setup()
  File "/usr/local/lib/python2.7/dist-packages/django/db/models/sql/compiler.py", line 47, in pre_sql_setup
    order_by = self.get_order_by()
  File "/usr/local/lib/python2.7/dist-packages/django/db/models/sql/compiler.py", line 298, in get_order_by
    field, self.query.get_meta(), default_order=asc))
  File "/usr/local/lib/python2.7/dist-packages/django/db/models/sql/compiler.py", line 593, in find_ordering_name
    field, targets, alias, joins, path, opts = self._setup_joins(pieces, opts, alias)
  File "/usr/local/lib/python2.7/dist-packages/django/db/models/sql/compiler.py", line 626, in _setup_joins
    pieces, opts, alias)
  File "/usr/local/lib/python2.7/dist-packages/django/db/models/sql/query.py", line 1417, in setup_joins
    names, opts, allow_many, fail_on_missing=True)
  File "/usr/local/lib/python2.7/dist-packages/django/db/models/sql/query.py", line 1352, in names_to_path
    "Choices are: %s" % (name, ", ".join(available)))
FieldError: Cannot resolve keyword 'end' into field. Choices are: builds, description, id, name, recipient, svn_password, svn_url, svn_username
2017-07-04 09:55:27,977 [uWSGIWorker2Core0:140242796070720] [django.request:135] [exception:handle_uncaught_exception] [ERROR]- Internal Server Error: /api/jobs/
Traceback (most recent call last):
  File "/usr/local/lib/python2.7/dist-packages/django/core/handlers/exception.py", line 41, in inner
    response = get_response(request)
  File "/usr/local/lib/python2.7/dist-packages/django/core/handlers/base.py", line 187, in _get_response
    response = self.process_exception_by_middleware(e, request)
  File "/usr/local/lib/python2.7/dist-packages/django/core/handlers/base.py", line 185, in _get_response
    response = wrapped_callback(request, *callback_args, **callback_kwargs)
  File "/usr/local/lib/python2.7/dist-packages/django/views/decorators/csrf.py", line 58, in wrapped_view
    return view_func(*args, **kwargs)
  File "/usr/local/lib/python2.7/dist-packages/rest_framework/viewsets.py", line 86, in view
    return self.dispatch(request, *args, **kwargs)
  File "/usr/local/lib/python2.7/dist-packages/rest_framework/views.py", line 489, in dispatch
    response = self.handle_exception(exc)
  File "/usr/local/lib/python2.7/dist-packages/rest_framework/views.py", line 449, in handle_exception
    self.raise_uncaught_exception(exc)
  File "/usr/local/lib/python2.7/dist-packages/rest_framework/views.py", line 486, in dispatch
    response = handler(request, *args, **kwargs)
  File "/usr/local/lib/python2.7/dist-packages/rest_framework/mixins.py", line 42, in list
    page = self.paginate_queryset(queryset)
  File "/usr/local/lib/python2.7/dist-packages/rest_framework/generics.py", line 173, in paginate_queryset
    return self.paginator.paginate_queryset(queryset, self.request, view=self)
  File "/usr/local/lib/python2.7/dist-packages/rest_framework/pagination.py", line 226, in paginate_queryset
    return list(self.page)
  File "/usr/local/lib/python2.7/dist-packages/django/core/paginator.py", line 137, in __len__
    return len(self.object_list)
  File "/usr/local/lib/python2.7/dist-packages/django/db/models/query.py", line 232, in __len__
    self._fetch_all()
  File "/usr/local/lib/python2.7/dist-packages/django/db/models/query.py", line 1118, in _fetch_all
    self._result_cache = list(self._iterable_class(self))
  File "/usr/local/lib/python2.7/dist-packages/django/db/models/query.py", line 53, in __iter__
    results = compiler.execute_sql(chunked_fetch=self.chunked_fetch)
  File "/usr/local/lib/python2.7/dist-packages/silk/sql.py", line 24, in execute_sql
    q, params = self.as_sql()
  File "/usr/local/lib/python2.7/dist-packages/django/db/models/sql/compiler.py", line 412, in as_sql
    extra_select, order_by, group_by = self.pre_sql_setup()
  File "/usr/local/lib/python2.7/dist-packages/django/db/models/sql/compiler.py", line 47, in pre_sql_setup
    order_by = self.get_order_by()
  File "/usr/local/lib/python2.7/dist-packages/django/db/models/sql/compiler.py", line 298, in get_order_by
    field, self.query.get_meta(), default_order=asc))
  File "/usr/local/lib/python2.7/dist-packages/django/db/models/sql/compiler.py", line 593, in find_ordering_name
    field, targets, alias, joins, path, opts = self._setup_joins(pieces, opts, alias)
  File "/usr/local/lib/python2.7/dist-packages/django/db/models/sql/compiler.py", line 626, in _setup_joins
    pieces, opts, alias)
  File "/usr/local/lib/python2.7/dist-packages/django/db/models/sql/query.py", line 1417, in setup_joins
    names, opts, allow_many, fail_on_missing=True)
  File "/usr/local/lib/python2.7/dist-packages/django/db/models/sql/query.py", line 1352, in names_to_path
    "Choices are: %s" % (name, ", ".join(available)))
FieldError: Cannot resolve keyword 'end' into field. Choices are: builds, description, id, name, recipient, svn_password, svn_url, svn_username
2017-07-04 09:55:28,225 [uWSGIWorker1Core0:140242796070720] [django.request:135] [exception:handle_uncaught_exception] [ERROR]- Internal Server Error: /api/jobs/
Traceback (most recent call last):
  File "/usr/local/lib/python2.7/dist-packages/django/core/handlers/exception.py", line 41, in inner
    response = get_response(request)
  File "/usr/local/lib/python2.7/dist-packages/django/core/handlers/base.py", line 187, in _get_response
    response = self.process_exception_by_middleware(e, request)
  File "/usr/local/lib/python2.7/dist-packages/django/core/handlers/base.py", line 185, in _get_response
    response = wrapped_callback(request, *callback_args, **callback_kwargs)
  File "/usr/local/lib/python2.7/dist-packages/django/views/decorators/csrf.py", line 58, in wrapped_view
    return view_func(*args, **kwargs)
  File "/usr/local/lib/python2.7/dist-packages/rest_framework/viewsets.py", line 86, in view
    return self.dispatch(request, *args, **kwargs)
  File "/usr/local/lib/python2.7/dist-packages/rest_framework/views.py", line 489, in dispatch
    response = self.handle_exception(exc)
  File "/usr/local/lib/python2.7/dist-packages/rest_framework/views.py", line 449, in handle_exception
    self.raise_uncaught_exception(exc)
  File "/usr/local/lib/python2.7/dist-packages/rest_framework/views.py", line 486, in dispatch
    response = handler(request, *args, **kwargs)
  File "/usr/local/lib/python2.7/dist-packages/rest_framework/mixins.py", line 42, in list
    page = self.paginate_queryset(queryset)
  File "/usr/local/lib/python2.7/dist-packages/rest_framework/generics.py", line 173, in paginate_queryset
    return self.paginator.paginate_queryset(queryset, self.request, view=self)
  File "/usr/local/lib/python2.7/dist-packages/rest_framework/pagination.py", line 226, in paginate_queryset
    return list(self.page)
  File "/usr/local/lib/python2.7/dist-packages/django/core/paginator.py", line 137, in __len__
    return len(self.object_list)
  File "/usr/local/lib/python2.7/dist-packages/django/db/models/query.py", line 232, in __len__
    self._fetch_all()
  File "/usr/local/lib/python2.7/dist-packages/django/db/models/query.py", line 1118, in _fetch_all
    self._result_cache = list(self._iterable_class(self))
  File "/usr/local/lib/python2.7/dist-packages/django/db/models/query.py", line 53, in __iter__
    results = compiler.execute_sql(chunked_fetch=self.chunked_fetch)
  File "/usr/local/lib/python2.7/dist-packages/silk/sql.py", line 24, in execute_sql
    q, params = self.as_sql()
  File "/usr/local/lib/python2.7/dist-packages/django/db/models/sql/compiler.py", line 412, in as_sql
    extra_select, order_by, group_by = self.pre_sql_setup()
  File "/usr/local/lib/python2.7/dist-packages/django/db/models/sql/compiler.py", line 47, in pre_sql_setup
    order_by = self.get_order_by()
  File "/usr/local/lib/python2.7/dist-packages/django/db/models/sql/compiler.py", line 298, in get_order_by
    field, self.query.get_meta(), default_order=asc))
  File "/usr/local/lib/python2.7/dist-packages/django/db/models/sql/compiler.py", line 593, in find_ordering_name
    field, targets, alias, joins, path, opts = self._setup_joins(pieces, opts, alias)
  File "/usr/local/lib/python2.7/dist-packages/django/db/models/sql/compiler.py", line 626, in _setup_joins
    pieces, opts, alias)
  File "/usr/local/lib/python2.7/dist-packages/django/db/models/sql/query.py", line 1417, in setup_joins
    names, opts, allow_many, fail_on_missing=True)
  File "/usr/local/lib/python2.7/dist-packages/django/db/models/sql/query.py", line 1352, in names_to_path
    "Choices are: %s" % (name, ", ".join(available)))
FieldError: Cannot resolve keyword 'end' into field. Choices are: builds, description, id, name, recipient, svn_password, svn_url, svn_username
2017-07-04 09:55:28,573 [uWSGIWorker3Core0:140242796070720] [django.request:135] [exception:handle_uncaught_exception] [ERROR]- Internal Server Error: /api/jobs/
Traceback (most recent call last):
  File "/usr/local/lib/python2.7/dist-packages/django/core/handlers/exception.py", line 41, in inner
    response = get_response(request)
  File "/usr/local/lib/python2.7/dist-packages/django/core/handlers/base.py", line 187, in _get_response
    response = self.process_exception_by_middleware(e, request)
  File "/usr/local/lib/python2.7/dist-packages/django/core/handlers/base.py", line 185, in _get_response
    response = wrapped_callback(request, *callback_args, **callback_kwargs)
  File "/usr/local/lib/python2.7/dist-packages/django/views/decorators/csrf.py", line 58, in wrapped_view
    return view_func(*args, **kwargs)
  File "/usr/local/lib/python2.7/dist-packages/rest_framework/viewsets.py", line 86, in view
    return self.dispatch(request, *args, **kwargs)
  File "/usr/local/lib/python2.7/dist-packages/rest_framework/views.py", line 489, in dispatch
    response = self.handle_exception(exc)
  File "/usr/local/lib/python2.7/dist-packages/rest_framework/views.py", line 449, in handle_exception
    self.raise_uncaught_exception(exc)
  File "/usr/local/lib/python2.7/dist-packages/rest_framework/views.py", line 486, in dispatch
    response = handler(request, *args, **kwargs)
  File "/usr/local/lib/python2.7/dist-packages/rest_framework/mixins.py", line 42, in list
    page = self.paginate_queryset(queryset)
  File "/usr/local/lib/python2.7/dist-packages/rest_framework/generics.py", line 173, in paginate_queryset
    return self.paginator.paginate_queryset(queryset, self.request, view=self)
  File "/usr/local/lib/python2.7/dist-packages/rest_framework/pagination.py", line 226, in paginate_queryset
    return list(self.page)
  File "/usr/local/lib/python2.7/dist-packages/django/core/paginator.py", line 137, in __len__
    return len(self.object_list)
  File "/usr/local/lib/python2.7/dist-packages/django/db/models/query.py", line 232, in __len__
    self._fetch_all()
  File "/usr/local/lib/python2.7/dist-packages/django/db/models/query.py", line 1118, in _fetch_all
    self._result_cache = list(self._iterable_class(self))
  File "/usr/local/lib/python2.7/dist-packages/django/db/models/query.py", line 53, in __iter__
    results = compiler.execute_sql(chunked_fetch=self.chunked_fetch)
  File "/usr/local/lib/python2.7/dist-packages/silk/sql.py", line 24, in execute_sql
    q, params = self.as_sql()
  File "/usr/local/lib/python2.7/dist-packages/django/db/models/sql/compiler.py", line 412, in as_sql
    extra_select, order_by, group_by = self.pre_sql_setup()
  File "/usr/local/lib/python2.7/dist-packages/django/db/models/sql/compiler.py", line 47, in pre_sql_setup
    order_by = self.get_order_by()
  File "/usr/local/lib/python2.7/dist-packages/django/db/models/sql/compiler.py", line 298, in get_order_by
    field, self.query.get_meta(), default_order=asc))
  File "/usr/local/lib/python2.7/dist-packages/django/db/models/sql/compiler.py", line 593, in find_ordering_name
    field, targets, alias, joins, path, opts = self._setup_joins(pieces, opts, alias)
  File "/usr/local/lib/python2.7/dist-packages/django/db/models/sql/compiler.py", line 626, in _setup_joins
    pieces, opts, alias)
  File "/usr/local/lib/python2.7/dist-packages/django/db/models/sql/query.py", line 1417, in setup_joins
    names, opts, allow_many, fail_on_missing=True)
  File "/usr/local/lib/python2.7/dist-packages/django/db/models/sql/query.py", line 1352, in names_to_path
    "Choices are: %s" % (name, ", ".join(available)))
FieldError: Cannot resolve keyword 'end' into field. Choices are: builds, description, id, name, recipient, svn_password, svn_url, svn_username
2017-07-04 09:55:40,803 [uWSGIWorker1Core0:140242796070720] [django.request:135] [exception:handle_uncaught_exception] [ERROR]- Internal Server Error: /api/jobs/
Traceback (most recent call last):
  File "/usr/local/lib/python2.7/dist-packages/django/core/handlers/exception.py", line 41, in inner
    response = get_response(request)
  File "/usr/local/lib/python2.7/dist-packages/django/core/handlers/base.py", line 187, in _get_response
    response = self.process_exception_by_middleware(e, request)
  File "/usr/local/lib/python2.7/dist-packages/django/core/handlers/base.py", line 185, in _get_response
    response = wrapped_callback(request, *callback_args, **callback_kwargs)
  File "/usr/local/lib/python2.7/dist-packages/django/views/decorators/csrf.py", line 58, in wrapped_view
    return view_func(*args, **kwargs)
  File "/usr/local/lib/python2.7/dist-packages/rest_framework/viewsets.py", line 86, in view
    return self.dispatch(request, *args, **kwargs)
  File "/usr/local/lib/python2.7/dist-packages/rest_framework/views.py", line 489, in dispatch
    response = self.handle_exception(exc)
  File "/usr/local/lib/python2.7/dist-packages/rest_framework/views.py", line 449, in handle_exception
    self.raise_uncaught_exception(exc)
  File "/usr/local/lib/python2.7/dist-packages/rest_framework/views.py", line 486, in dispatch
    response = handler(request, *args, **kwargs)
  File "/usr/local/lib/python2.7/dist-packages/rest_framework/mixins.py", line 42, in list
    page = self.paginate_queryset(queryset)
  File "/usr/local/lib/python2.7/dist-packages/rest_framework/generics.py", line 173, in paginate_queryset
    return self.paginator.paginate_queryset(queryset, self.request, view=self)
  File "/usr/local/lib/python2.7/dist-packages/rest_framework/pagination.py", line 226, in paginate_queryset
    return list(self.page)
  File "/usr/local/lib/python2.7/dist-packages/django/core/paginator.py", line 137, in __len__
    return len(self.object_list)
  File "/usr/local/lib/python2.7/dist-packages/django/db/models/query.py", line 232, in __len__
    self._fetch_all()
  File "/usr/local/lib/python2.7/dist-packages/django/db/models/query.py", line 1118, in _fetch_all
    self._result_cache = list(self._iterable_class(self))
  File "/usr/local/lib/python2.7/dist-packages/django/db/models/query.py", line 53, in __iter__
    results = compiler.execute_sql(chunked_fetch=self.chunked_fetch)
  File "/usr/local/lib/python2.7/dist-packages/silk/sql.py", line 24, in execute_sql
    q, params = self.as_sql()
  File "/usr/local/lib/python2.7/dist-packages/django/db/models/sql/compiler.py", line 412, in as_sql
    extra_select, order_by, group_by = self.pre_sql_setup()
  File "/usr/local/lib/python2.7/dist-packages/django/db/models/sql/compiler.py", line 47, in pre_sql_setup
    order_by = self.get_order_by()
  File "/usr/local/lib/python2.7/dist-packages/django/db/models/sql/compiler.py", line 298, in get_order_by
    field, self.query.get_meta(), default_order=asc))
  File "/usr/local/lib/python2.7/dist-packages/django/db/models/sql/compiler.py", line 593, in find_ordering_name
    field, targets, alias, joins, path, opts = self._setup_joins(pieces, opts, alias)
  File "/usr/local/lib/python2.7/dist-packages/django/db/models/sql/compiler.py", line 626, in _setup_joins
    pieces, opts, alias)
  File "/usr/local/lib/python2.7/dist-packages/django/db/models/sql/query.py", line 1417, in setup_joins
    names, opts, allow_many, fail_on_missing=True)
  File "/usr/local/lib/python2.7/dist-packages/django/db/models/sql/query.py", line 1352, in names_to_path
    "Choices are: %s" % (name, ", ".join(available)))
FieldError: Cannot resolve keyword 'end' into field. Choices are: builds, description, id, name, recipient, svn_password, svn_url, svn_username
2017-07-04 09:55:49,320 [uWSGIWorker2Core0:140242796070720] [django.request:135] [exception:handle_uncaught_exception] [ERROR]- Internal Server Error: /api/jobs/
Traceback (most recent call last):
  File "/usr/local/lib/python2.7/dist-packages/django/core/handlers/exception.py", line 41, in inner
    response = get_response(request)
  File "/usr/local/lib/python2.7/dist-packages/django/core/handlers/base.py", line 187, in _get_response
    response = self.process_exception_by_middleware(e, request)
  File "/usr/local/lib/python2.7/dist-packages/django/core/handlers/base.py", line 185, in _get_response
    response = wrapped_callback(request, *callback_args, **callback_kwargs)
  File "/usr/local/lib/python2.7/dist-packages/django/views/decorators/csrf.py", line 58, in wrapped_view
    return view_func(*args, **kwargs)
  File "/usr/local/lib/python2.7/dist-packages/rest_framework/viewsets.py", line 86, in view
    return self.dispatch(request, *args, **kwargs)
  File "/usr/local/lib/python2.7/dist-packages/rest_framework/views.py", line 489, in dispatch
    response = self.handle_exception(exc)
  File "/usr/local/lib/python2.7/dist-packages/rest_framework/views.py", line 449, in handle_exception
    self.raise_uncaught_exception(exc)
  File "/usr/local/lib/python2.7/dist-packages/rest_framework/views.py", line 486, in dispatch
    response = handler(request, *args, **kwargs)
  File "/usr/local/lib/python2.7/dist-packages/rest_framework/mixins.py", line 42, in list
    page = self.paginate_queryset(queryset)
  File "/usr/local/lib/python2.7/dist-packages/rest_framework/generics.py", line 173, in paginate_queryset
    return self.paginator.paginate_queryset(queryset, self.request, view=self)
  File "/usr/local/lib/python2.7/dist-packages/rest_framework/pagination.py", line 226, in paginate_queryset
    return list(self.page)
  File "/usr/local/lib/python2.7/dist-packages/django/core/paginator.py", line 137, in __len__
    return len(self.object_list)
  File "/usr/local/lib/python2.7/dist-packages/django/db/models/query.py", line 232, in __len__
    self._fetch_all()
  File "/usr/local/lib/python2.7/dist-packages/django/db/models/query.py", line 1118, in _fetch_all
    self._result_cache = list(self._iterable_class(self))
  File "/usr/local/lib/python2.7/dist-packages/django/db/models/query.py", line 53, in __iter__
    results = compiler.execute_sql(chunked_fetch=self.chunked_fetch)
  File "/usr/local/lib/python2.7/dist-packages/silk/sql.py", line 24, in execute_sql
    q, params = self.as_sql()
  File "/usr/local/lib/python2.7/dist-packages/django/db/models/sql/compiler.py", line 412, in as_sql
    extra_select, order_by, group_by = self.pre_sql_setup()
  File "/usr/local/lib/python2.7/dist-packages/django/db/models/sql/compiler.py", line 47, in pre_sql_setup
    order_by = self.get_order_by()
  File "/usr/local/lib/python2.7/dist-packages/django/db/models/sql/compiler.py", line 298, in get_order_by
    field, self.query.get_meta(), default_order=asc))
  File "/usr/local/lib/python2.7/dist-packages/django/db/models/sql/compiler.py", line 593, in find_ordering_name
    field, targets, alias, joins, path, opts = self._setup_joins(pieces, opts, alias)
  File "/usr/local/lib/python2.7/dist-packages/django/db/models/sql/compiler.py", line 626, in _setup_joins
    pieces, opts, alias)
  File "/usr/local/lib/python2.7/dist-packages/django/db/models/sql/query.py", line 1417, in setup_joins
    names, opts, allow_many, fail_on_missing=True)
  File "/usr/local/lib/python2.7/dist-packages/django/db/models/sql/query.py", line 1352, in names_to_path
    "Choices are: %s" % (name, ", ".join(available)))
FieldError: Cannot resolve keyword 'end' into field. Choices are: builds, description, id, name, recipient, svn_password, svn_url, svn_username
2017-07-04 09:56:04,908 [uWSGIWorker1Core0:140242796070720] [django.request:135] [exception:handle_uncaught_exception] [ERROR]- Internal Server Error: /api/jobs/
Traceback (most recent call last):
  File "/usr/local/lib/python2.7/dist-packages/django/core/handlers/exception.py", line 41, in inner
    response = get_response(request)
  File "/usr/local/lib/python2.7/dist-packages/django/core/handlers/base.py", line 187, in _get_response
    response = self.process_exception_by_middleware(e, request)
  File "/usr/local/lib/python2.7/dist-packages/django/core/handlers/base.py", line 185, in _get_response
    response = wrapped_callback(request, *callback_args, **callback_kwargs)
  File "/usr/local/lib/python2.7/dist-packages/django/views/decorators/csrf.py", line 58, in wrapped_view
    return view_func(*args, **kwargs)
  File "/usr/local/lib/python2.7/dist-packages/rest_framework/viewsets.py", line 86, in view
    return self.dispatch(request, *args, **kwargs)
  File "/usr/local/lib/python2.7/dist-packages/rest_framework/views.py", line 489, in dispatch
    response = self.handle_exception(exc)
  File "/usr/local/lib/python2.7/dist-packages/rest_framework/views.py", line 449, in handle_exception
    self.raise_uncaught_exception(exc)
  File "/usr/local/lib/python2.7/dist-packages/rest_framework/views.py", line 486, in dispatch
    response = handler(request, *args, **kwargs)
  File "/usr/local/lib/python2.7/dist-packages/rest_framework/mixins.py", line 42, in list
    page = self.paginate_queryset(queryset)
  File "/usr/local/lib/python2.7/dist-packages/rest_framework/generics.py", line 173, in paginate_queryset
    return self.paginator.paginate_queryset(queryset, self.request, view=self)
  File "/usr/local/lib/python2.7/dist-packages/rest_framework/pagination.py", line 226, in paginate_queryset
    return list(self.page)
  File "/usr/local/lib/python2.7/dist-packages/django/core/paginator.py", line 137, in __len__
    return len(self.object_list)
  File "/usr/local/lib/python2.7/dist-packages/django/db/models/query.py", line 232, in __len__
    self._fetch_all()
  File "/usr/local/lib/python2.7/dist-packages/django/db/models/query.py", line 1118, in _fetch_all
    self._result_cache = list(self._iterable_class(self))
  File "/usr/local/lib/python2.7/dist-packages/django/db/models/query.py", line 53, in __iter__
    results = compiler.execute_sql(chunked_fetch=self.chunked_fetch)
  File "/usr/local/lib/python2.7/dist-packages/silk/sql.py", line 24, in execute_sql
    q, params = self.as_sql()
  File "/usr/local/lib/python2.7/dist-packages/django/db/models/sql/compiler.py", line 412, in as_sql
    extra_select, order_by, group_by = self.pre_sql_setup()
  File "/usr/local/lib/python2.7/dist-packages/django/db/models/sql/compiler.py", line 47, in pre_sql_setup
    order_by = self.get_order_by()
  File "/usr/local/lib/python2.7/dist-packages/django/db/models/sql/compiler.py", line 298, in get_order_by
    field, self.query.get_meta(), default_order=asc))
  File "/usr/local/lib/python2.7/dist-packages/django/db/models/sql/compiler.py", line 593, in find_ordering_name
    field, targets, alias, joins, path, opts = self._setup_joins(pieces, opts, alias)
  File "/usr/local/lib/python2.7/dist-packages/django/db/models/sql/compiler.py", line 626, in _setup_joins
    pieces, opts, alias)
  File "/usr/local/lib/python2.7/dist-packages/django/db/models/sql/query.py", line 1417, in setup_joins
    names, opts, allow_many, fail_on_missing=True)
  File "/usr/local/lib/python2.7/dist-packages/django/db/models/sql/query.py", line 1352, in names_to_path
    "Choices are: %s" % (name, ", ".join(available)))
FieldError: Cannot resolve keyword 'end' into field. Choices are: builds, description, id, name, recipient, svn_password, svn_url, svn_username
2017-07-04 10:06:11,243 [uWSGIWorker2Core0:140006669625152] [django.request:135] [exception:handle_uncaught_exception] [ERROR]- Internal Server Error: /api/builds/
Traceback (most recent call last):
  File "/usr/local/lib/python2.7/dist-packages/django/core/handlers/exception.py", line 41, in inner
    response = get_response(request)
  File "/usr/local/lib/python2.7/dist-packages/django/core/handlers/base.py", line 217, in _get_response
    response = self.process_exception_by_middleware(e, request)
  File "/usr/local/lib/python2.7/dist-packages/django/core/handlers/base.py", line 215, in _get_response
    response = response.render()
  File "/usr/local/lib/python2.7/dist-packages/django/template/response.py", line 107, in render
    self.content = self.rendered_content
  File "/usr/local/lib/python2.7/dist-packages/rest_framework/response.py", line 72, in rendered_content
    ret = renderer.render(self.data, accepted_media_type, context)
  File "/usr/local/lib/python2.7/dist-packages/rest_framework/renderers.py", line 703, in render
    context = self.get_context(data, accepted_media_type, renderer_context)
  File "/usr/local/lib/python2.7/dist-packages/rest_framework/renderers.py", line 636, in get_context
    raw_data_post_form = self.get_raw_data_form(data, view, 'POST', request)
  File "/usr/local/lib/python2.7/dist-packages/rest_framework/renderers.py", line 559, in get_raw_data_form
    content = renderer.render(serializer.data, accepted, context)
  File "/usr/local/lib/python2.7/dist-packages/rest_framework/serializers.py", line 534, in data
    ret = super(Serializer, self).data
  File "/usr/local/lib/python2.7/dist-packages/rest_framework/serializers.py", line 267, in data
    self._data = self.get_initial()
  File "/usr/local/lib/python2.7/dist-packages/rest_framework/serializers.py", line 411, in get_initial
    for field in self.fields.values()
  File "/usr/local/lib/python2.7/dist-packages/rest_framework/serializers.py", line 364, in fields
    for key, value in self.get_fields().items():
  File "/usr/local/lib/python2.7/dist-packages/rest_framework/serializers.py", line 1017, in get_fields
    source, info, model, depth
  File "/usr/local/lib/python2.7/dist-packages/rest_framework/serializers.py", line 1151, in build_field
    return self.build_unknown_field(field_name, model_class)
  File "/usr/local/lib/python2.7/dist-packages/rest_framework/serializers.py", line 1258, in build_unknown_field
    (field_name, model_class.__name__)
ImproperlyConfigured: Field name `updated` is not valid for model `Build`.
2017-07-04 10:06:51,357 [uWSGIWorker1Core0:140006669625152] [django.request:135] [exception:handle_uncaught_exception] [ERROR]- Internal Server Error: /api/builds/
Traceback (most recent call last):
  File "/usr/local/lib/python2.7/dist-packages/django/core/handlers/exception.py", line 41, in inner
    response = get_response(request)
  File "/usr/local/lib/python2.7/dist-packages/django/core/handlers/base.py", line 217, in _get_response
    response = self.process_exception_by_middleware(e, request)
  File "/usr/local/lib/python2.7/dist-packages/django/core/handlers/base.py", line 215, in _get_response
    response = response.render()
  File "/usr/local/lib/python2.7/dist-packages/django/template/response.py", line 107, in render
    self.content = self.rendered_content
  File "/usr/local/lib/python2.7/dist-packages/rest_framework/response.py", line 72, in rendered_content
    ret = renderer.render(self.data, accepted_media_type, context)
  File "/usr/local/lib/python2.7/dist-packages/rest_framework/renderers.py", line 703, in render
    context = self.get_context(data, accepted_media_type, renderer_context)
  File "/usr/local/lib/python2.7/dist-packages/rest_framework/renderers.py", line 636, in get_context
    raw_data_post_form = self.get_raw_data_form(data, view, 'POST', request)
  File "/usr/local/lib/python2.7/dist-packages/rest_framework/renderers.py", line 559, in get_raw_data_form
    content = renderer.render(serializer.data, accepted, context)
  File "/usr/local/lib/python2.7/dist-packages/rest_framework/serializers.py", line 534, in data
    ret = super(Serializer, self).data
  File "/usr/local/lib/python2.7/dist-packages/rest_framework/serializers.py", line 267, in data
    self._data = self.get_initial()
  File "/usr/local/lib/python2.7/dist-packages/rest_framework/serializers.py", line 411, in get_initial
    for field in self.fields.values()
  File "/usr/local/lib/python2.7/dist-packages/rest_framework/serializers.py", line 364, in fields
    for key, value in self.get_fields().items():
  File "/usr/local/lib/python2.7/dist-packages/rest_framework/serializers.py", line 1017, in get_fields
    source, info, model, depth
  File "/usr/local/lib/python2.7/dist-packages/rest_framework/serializers.py", line 1151, in build_field
    return self.build_unknown_field(field_name, model_class)
  File "/usr/local/lib/python2.7/dist-packages/rest_framework/serializers.py", line 1258, in build_unknown_field
    (field_name, model_class.__name__)
ImproperlyConfigured: Field name `updated` is not valid for model `Build`.
2017-07-04 10:06:52,972 [uWSGIWorker2Core0:140006669625152] [django.request:135] [exception:handle_uncaught_exception] [ERROR]- Internal Server Error: /api/builds/
Traceback (most recent call last):
  File "/usr/local/lib/python2.7/dist-packages/django/core/handlers/exception.py", line 41, in inner
    response = get_response(request)
  File "/usr/local/lib/python2.7/dist-packages/django/core/handlers/base.py", line 217, in _get_response
    response = self.process_exception_by_middleware(e, request)
  File "/usr/local/lib/python2.7/dist-packages/django/core/handlers/base.py", line 215, in _get_response
    response = response.render()
  File "/usr/local/lib/python2.7/dist-packages/django/template/response.py", line 107, in render
    self.content = self.rendered_content
  File "/usr/local/lib/python2.7/dist-packages/rest_framework/response.py", line 72, in rendered_content
    ret = renderer.render(self.data, accepted_media_type, context)
  File "/usr/local/lib/python2.7/dist-packages/rest_framework/renderers.py", line 703, in render
    context = self.get_context(data, accepted_media_type, renderer_context)
  File "/usr/local/lib/python2.7/dist-packages/rest_framework/renderers.py", line 636, in get_context
    raw_data_post_form = self.get_raw_data_form(data, view, 'POST', request)
  File "/usr/local/lib/python2.7/dist-packages/rest_framework/renderers.py", line 559, in get_raw_data_form
    content = renderer.render(serializer.data, accepted, context)
  File "/usr/local/lib/python2.7/dist-packages/rest_framework/serializers.py", line 534, in data
    ret = super(Serializer, self).data
  File "/usr/local/lib/python2.7/dist-packages/rest_framework/serializers.py", line 267, in data
    self._data = self.get_initial()
  File "/usr/local/lib/python2.7/dist-packages/rest_framework/serializers.py", line 411, in get_initial
    for field in self.fields.values()
  File "/usr/local/lib/python2.7/dist-packages/rest_framework/serializers.py", line 364, in fields
    for key, value in self.get_fields().items():
  File "/usr/local/lib/python2.7/dist-packages/rest_framework/serializers.py", line 1017, in get_fields
    source, info, model, depth
  File "/usr/local/lib/python2.7/dist-packages/rest_framework/serializers.py", line 1151, in build_field
    return self.build_unknown_field(field_name, model_class)
  File "/usr/local/lib/python2.7/dist-packages/rest_framework/serializers.py", line 1258, in build_unknown_field
    (field_name, model_class.__name__)
ImproperlyConfigured: Field name `updated` is not valid for model `Build`.
2017-07-04 10:19:53,145 [uWSGIWorker2Core0:140692229285696] [django.request:135] [exception:handle_uncaught_exception] [ERROR]- Internal Server Error: /api/jobs/
Traceback (most recent call last):
  File "/usr/local/lib/python2.7/dist-packages/django/core/handlers/exception.py", line 41, in inner
    response = get_response(request)
  File "/usr/local/lib/python2.7/dist-packages/django/core/handlers/base.py", line 187, in _get_response
    response = self.process_exception_by_middleware(e, request)
  File "/usr/local/lib/python2.7/dist-packages/django/core/handlers/base.py", line 185, in _get_response
    response = wrapped_callback(request, *callback_args, **callback_kwargs)
  File "/usr/local/lib/python2.7/dist-packages/django/views/decorators/csrf.py", line 58, in wrapped_view
    return view_func(*args, **kwargs)
  File "/usr/local/lib/python2.7/dist-packages/rest_framework/viewsets.py", line 86, in view
    return self.dispatch(request, *args, **kwargs)
  File "/usr/local/lib/python2.7/dist-packages/rest_framework/views.py", line 489, in dispatch
    response = self.handle_exception(exc)
  File "/usr/local/lib/python2.7/dist-packages/rest_framework/views.py", line 449, in handle_exception
    self.raise_uncaught_exception(exc)
  File "/usr/local/lib/python2.7/dist-packages/rest_framework/views.py", line 486, in dispatch
    response = handler(request, *args, **kwargs)
  File "/usr/local/lib/python2.7/dist-packages/rest_framework/mixins.py", line 45, in list
    return self.get_paginated_response(serializer.data)
  File "/usr/local/lib/python2.7/dist-packages/rest_framework/serializers.py", line 739, in data
    ret = super(ListSerializer, self).data
  File "/usr/local/lib/python2.7/dist-packages/rest_framework/serializers.py", line 263, in data
    self._data = self.to_representation(self.instance)
  File "/usr/local/lib/python2.7/dist-packages/rest_framework/serializers.py", line 657, in to_representation
    self.child.to_representation(item) for item in iterable
  File "/usr/local/lib/python2.7/dist-packages/rest_framework/serializers.py", line 501, in to_representation
    ret[field.field_name] = field.to_representation(attribute)
  File "/usr/local/lib/python2.7/dist-packages/rest_framework/fields.py", line 1754, in to_representation
    return method(value)
  File "./app/serializers.py", line 28, in get_violation_info
    return json.loads(last_build.result).get('violation_info')
  File "/usr/lib/python2.7/json/__init__.py", line 338, in loads
    return _default_decoder.decode(s)
  File "/usr/lib/python2.7/json/decoder.py", line 366, in decode
    obj, end = self.raw_decode(s, idx=_w(s, 0).end())
  File "/usr/lib/python2.7/json/decoder.py", line 384, in raw_decode
    raise ValueError("No JSON object could be decoded")
ValueError: No JSON object could be decoded
2017-07-04 10:25:16,628 [uWSGIWorker2Core0:140692229285696] [django.request:135] [exception:handle_uncaught_exception] [ERROR]- Internal Server Error: /api/jobs/1/
Traceback (most recent call last):
  File "/usr/local/lib/python2.7/dist-packages/django/core/handlers/exception.py", line 41, in inner
    response = get_response(request)
  File "/usr/local/lib/python2.7/dist-packages/django/core/handlers/base.py", line 187, in _get_response
    response = self.process_exception_by_middleware(e, request)
  File "/usr/local/lib/python2.7/dist-packages/django/core/handlers/base.py", line 185, in _get_response
    response = wrapped_callback(request, *callback_args, **callback_kwargs)
  File "/usr/local/lib/python2.7/dist-packages/django/views/decorators/csrf.py", line 58, in wrapped_view
    return view_func(*args, **kwargs)
  File "/usr/local/lib/python2.7/dist-packages/rest_framework/viewsets.py", line 86, in view
    return self.dispatch(request, *args, **kwargs)
  File "/usr/local/lib/python2.7/dist-packages/rest_framework/views.py", line 489, in dispatch
    response = self.handle_exception(exc)
  File "/usr/local/lib/python2.7/dist-packages/rest_framework/views.py", line 449, in handle_exception
    self.raise_uncaught_exception(exc)
  File "/usr/local/lib/python2.7/dist-packages/rest_framework/views.py", line 486, in dispatch
    response = handler(request, *args, **kwargs)
  File "/usr/local/lib/python2.7/dist-packages/rest_framework/mixins.py", line 58, in retrieve
    return Response(serializer.data)
  File "/usr/local/lib/python2.7/dist-packages/rest_framework/serializers.py", line 534, in data
    ret = super(Serializer, self).data
  File "/usr/local/lib/python2.7/dist-packages/rest_framework/serializers.py", line 263, in data
    self._data = self.to_representation(self.instance)
  File "/usr/local/lib/python2.7/dist-packages/rest_framework/serializers.py", line 501, in to_representation
    ret[field.field_name] = field.to_representation(attribute)
  File "/usr/local/lib/python2.7/dist-packages/rest_framework/fields.py", line 1754, in to_representation
    return method(value)
  File "./app/serializers.py", line 28, in get_violation_info
    return json.loads(last_build.result).get('violation_info')
  File "/usr/lib/python2.7/json/__init__.py", line 338, in loads
    return _default_decoder.decode(s)
  File "/usr/lib/python2.7/json/decoder.py", line 366, in decode
    obj, end = self.raw_decode(s, idx=_w(s, 0).end())
  File "/usr/lib/python2.7/json/decoder.py", line 384, in raw_decode
    raise ValueError("No JSON object could be decoded")
ValueError: No JSON object could be decoded
